Workbook

Sheet الملخص
A1: ملخص الوظائف حسب الموديول والتطبيق
A2: الأعداد محسوبة بمعادلات من ورقة «قائمة الوظائف». «ضمن النطاق» = المخطط التفصيلي + قائمة وظائف المورّد (محسوبة افتراضياً)؛ «من واقع الخبرة» = مقترحة وغير محسوبة حتى يقرر الفريق تضمينها.
A4: الموديول (الإدارة) | B4: التطبيق | C4: Application | D4: تابع لـ / ملاحظات | E4: إجمالي الوظائف | F4: المخطط التفصيلي | G4: قائمة المورّد | H4: من واقع الخبرة | I4: محسوبة افتراضياً | J4: يعمل تشغيلياً (حسب المورّد)
A5: إدارة الموارد البشرية والخدمات | B5: شؤون العاملين | C5: Personnel Affairs | E5: =COUNTIFS('قائمة الوظائف'!$D$5:$D$517,$B5) -> 40 | F5: =COUNTIFS('قائمة الوظائف'!$D$5:$D$517,$B5,'قائمة الوظائف'!$J$5:$J$517,"المخطط التفصيلي") -> 20 | G5: =COUNTIFS('قائمة الوظائف'!$D$5:$D$517,$B5,'قائمة الوظائف'!$J$5:$J$517,"قائمة وظائف المورّد") -> 13 | H5: =COUNTIFS('قائمة الوظائف'!$D$5:$D$517,$B5,'قائمة الوظائف'!$J$5:$J$517,"من واقع الخبرة") -> 7 | I5: =COUNTIFS('قائمة الوظائف'!$D$5:$D$517,$B5,'قائمة الوظائف'!$M$5:$M$517,"نعم") -> 33 | J5: =COUNTIFS('قائمة الوظائف'!$D$5:$D$517,$B5,'قائمة الوظائف'!$L$5:$L$517,"يعمل تشغيلياً") -> 10
A6: إدارة الموارد البشرية والخدمات | B6: التوظيف | C6: Recruitment | D6: ضمن شؤون العاملين | E6: =COUNTIFS('قائمة الوظائف'!$D$5:$D$517,$B6) -> 15 | F6: =COUNTIFS('قائمة الوظائف'!$D$5:$D$517,$B6,'قائمة الوظائف'!$J$5:$J$517,"المخطط التفصيلي") -> 13 | G6: =COUNTIFS('قائمة الوظائف'!$D$5:$D$517,$B6,'قائمة الوظائف'!$J$5:$J$517,"قائمة وظائف المورّد") -> 1 | H6: =COUNTIFS('قائمة الوظائف'!$D$5:$D$517,$B6,'قائمة الوظائف'!$J$5:$J$517,"من واقع الخبرة") -> 1 | I6: =COUNTIFS('قائمة الوظائف'!$D$5:$D$517,$B6,'قائمة الوظائف'!$M$5:$M$517,"نعم") -> 14 | J6: =COUNTIFS('قائمة الوظائف'!$D$5:$D$517,$B6,'قائمة الوظائف'!$L$5:$L$517,"يعمل تشغيلياً") -> 1
A7: إدارة الموارد البشرية والخدمات | B7: الحضور والانصراف | C7: Time & Attendance | E7: =COUNTIFS('قائمة الوظائف'!$D$5:$D$517,$B7) -> 33 | F7: =COUNTIFS('قائمة الوظائف'!$D$5:$D$517,$B7,'قائمة الوظائف'!$J$5:$J$517,"المخطط التفصيلي") -> 13 | G7: =COUNTIFS('قائمة الوظائف'!$D$5:$D$517,$B7,'قائمة الوظائف'!$J$5:$J$517,"قائمة وظائف المورّد") -> 18 | H7: =COUNTIFS('قائمة الوظائف'!$D$5:$D$517,$B7,'قائمة الوظائف'!$J$5:$J$517,"من واقع الخبرة") -> 2 | I7: =COUNTIFS('قائمة الوظائف'!$D$5:$D$517,$B7,'قائمة الوظائف'!$M$5:$M$517,"نعم") -> 31 | J7: =COUNTIFS('قائمة الوظائف'!$D$5:$D$517,$B7,'قائمة الوظائف'!$L$5:$L$517,"يعمل تشغيلياً") -> 17
A8: إدارة الموارد البشرية والخدمات | B8: الإجازات | C8: Leave | E8: =COUNTIFS('قائمة الوظائف'!$D$5:$D$517,$B8) -> 15 | F8: =COUNTIFS('قائمة الوظائف'!$D$5:$D$517,$B8,'قائمة الوظائف'!$J$5:$J$517,"المخطط التفصيلي") -> 5 | G8: =COUNTIFS('قائمة الوظائف'!$D$5:$D$517,$B8,'قائمة الوظائف'!$J$5:$J$517,"قائمة وظائف المورّد") -> 7 | H8: =COUNTIFS('قائمة الوظائف'!$D$5:$D$517,$B8,'قائمة الوظائف'!$J$5:$J$517,"من واقع الخبرة") -> 3 | I8: =COUNTIFS('قائمة الوظائف'!$D$5:$D$517,$B8,'قائمة الوظائف'!$M$5:$M$517,"نعم") -> 12 | J8: =COUNTIFS('قائمة الوظائف'!$D$5:$D$517,$B8,'قائمة الوظائف'!$L$5:$L$517,"يعمل تشغيلياً") -> 7
A9: إدارة الموارد البشرية والخدمات | B9: المرتبات والسلف | C9: Payroll & Advances | E9: =COUNTIFS('قائمة الوظائف'!$D$5:$D$517,$B9) -> 32 | F9: =COUNTIFS('قائمة الوظائف'!$D$5:$D$517,$B9,'قائمة الوظائف'!$J$5:$J$517,"المخطط التفصيلي") -> 14 | G9: =COUNTIFS('قائمة الوظائف'!$D$5:$D$517,$B9,'قائمة الوظائف'!$J$5:$J$517,"قائمة وظائف المورّد") -> 11 | H9: =COUNTIFS('قائمة الوظائف'!$D$5:$D$517,$B9,'قائمة الوظائف'!$J$5:$J$517,"من واقع الخبرة") -> 7 | I9: =COUNTIFS('قائمة الوظائف'!$D$5:$D$517,$B9,'قائمة الوظائف'!$M$5:$M$517,"نعم") -> 25 | J9: =COUNTIFS('قائمة الوظائف'!$D$5:$D$517,$B9,'قائمة الوظائف'!$L$5:$L$517,"يعمل تشغيلياً") -> 8
A10: إدارة الموارد البشرية والخدمات | B10: التقييم | C10: Appraisal | D10: ضمن المرتبات | E10: =COUNTIFS('قائمة الوظائف'!$D$5:$D$517,$B10) -> 14 | F10: =COUNTIFS('قائمة الوظائف'!$D$5:$D$517,$B10,'قائمة الوظائف'!$J$5:$J$517,"المخطط التفصيلي") -> 8 | G10: =COUNTIFS('قائمة الوظائف'!$D$5:$D$517,$B10,'قائمة الوظائف'!$J$5:$J$517,"قائمة وظائف المورّد") -> 2 | H10: =COUNTIFS('قائمة الوظائف'!$D$5:$D$517,$B10,'قائمة الوظائف'!$J$5:$J$517,"من واقع الخبرة") -> 4 | I10: =COUNTIFS('قائمة الوظائف'!$D$5:$D$517,$B10,'قائمة الوظائف'!$M$5:$M$517,"نعم") -> 10 | J10: =COUNTIFS('قائمة الوظائف'!$D$5:$D$517,$B10,'قائمة الوظائف'!$L$5:$L$517,"يعمل تشغيلياً") -> 1
A11: إدارة الموارد البشرية والخدمات | B11: الطلبات ومسارات الاعتماد | C11: Requests & Approval Workflows | D11: وحدة غير واردة في المخطط | E11: =COUNTIFS('قائمة الوظائف'!$D$5:$D$517,$B11) -> 11 | F11: =COUNTIFS('قائمة الوظائف'!$D$5:$D$517,$B11,'قائمة الوظائف'!$J$5:$J$517,"المخطط التفصيلي") -> 0 | G11: =COUNTIFS('قائمة الوظائف'!$D$5:$D$517,$B11,'قائمة الوظائف'!$J$5:$J$517,"قائمة وظائف المورّد") -> 11 | H11: =COUNTIFS('قائمة الوظائف'!$D$5:$D$517,$B11,'قائمة الوظائف'!$J$5:$J$517,"من واقع الخبرة") -> 0 | I11: =COUNTIFS('قائمة الوظائف'!$D$5:$D$517,$B11,'قائمة الوظائف'!$M$5:$M$517,"نعم") -> 11 | J11: =COUNTIFS('قائمة الوظائف'!$D$5:$D$517,$B11,'قائمة الوظائف'!$L$5:$L$517,"يعمل تشغيلياً") -> 11
A12: إدارة الموارد البشرية والخدمات | B12: الخدمة الذاتية وتطبيق الجوال | C12: Employee Self-Service & Mobile App | D12: وحدة غير واردة في المخطط | E12: =COUNTIFS('قائمة الوظائف'!$D$5:$D$517,$B12) -> 7 | F12: =COUNTIFS('قائمة الوظائف'!$D$5:$D$517,$B12,'قائمة الوظائف'!$J$5:$J$517,"المخطط التفصيلي") -> 0 | G12: =COUNTIFS('قائمة الوظائف'!$D$5:$D$517,$B12,'قائمة الوظائف'!$J$5:$J$517,"قائمة وظائف المورّد") -> 7 | H12: =COUNTIFS('قائمة الوظائف'!$D$5:$D$517,$B12,'قائمة الوظائف'!$J$5:$J$517,"من واقع الخبرة") -> 0 | I12: =COUNTIFS('قائمة الوظائف'!$D$5:$D$517,$B12,'قائمة الوظائف'!$M$5:$M$517,"نعم") -> 7 | J12: =COUNTIFS('قائمة الوظائف'!$D$5:$D$517,$B12,'قائمة الوظائف'!$L$5:$L$517,"يعمل تشغيلياً") -> 7
A13: إدارة الموارد البشرية والخدمات | B13: المشتريات | C13: Purchasing | E13: =COUNTIFS('قائمة الوظائف'!$D$5:$D$517,$B13) -> 30 | F13: =COUNTIFS('قائمة الوظائف'!$D$5:$D$517,$B13,'قائمة الوظائف'!$J$5:$J$517,"المخطط التفصيلي") -> 15 | G13: =COUNTIFS('قائمة الوظائف'!$D$5:$D$517,$B13,'قائمة الوظائف'!$J$5:$J$517,"قائمة وظائف المورّد") -> 6 | H13: =COUNTIFS('قائمة الوظائف'!$D$5:$D$517,$B13,'قائمة الوظائف'!$J$5:$J$517,"من واقع الخبرة") -> 9 | I13: =COUNTIFS('قائمة الوظائف'!$D$5:$D$517,$B13,'قائمة الوظائف'!$M$5:$M$517,"نعم") -> 21 | J13: =COUNTIFS('قائمة الوظائف'!$D$5:$D$517,$B13,'قائمة الوظائف'!$L$5:$L$517,"يعمل تشغيلياً") -> 1
A14: إدارة الموارد البشرية والخدمات | B14: المخازن | C14: Inventory / Stores | E14: =COUNTIFS('قائمة الوظائف'!$D$5:$D$517,$B14) -> 29 | F14: =COUNTIFS('قائمة الوظائف'!$D$5:$D$517,$B14,'قائمة الوظائف'!$J$5:$J$517,"المخطط التفصيلي") -> 15 | G14: =COUNTIFS('قائمة الوظائف'!$D$5:$D$517,$B14,'قائمة الوظائف'!$J$5:$J$517,"قائمة وظائف المورّد") -> 7 | H14: =COUNTIFS('قائمة الوظائف'!$D$5:$D$517,$B14,'قائمة الوظائف'!$J$5:$J$517,"من واقع الخبرة") -> 7 | I14: =COUNTIFS('قائمة الوظائف'!$D$5:$D$517,$B14,'قائمة الوظائف'!$M$5:$M$517,"نعم") -> 22 | J14: =COUNTIFS('قائمة الوظائف'!$D$5:$D$517,$B14,'قائمة الوظائف'!$L$5:$L$517,"يعمل تشغيلياً") -> 6
A15: إدارة الموارد البشرية والخدمات | B15: التدريب والتطوير | C15: Training & Development | D15: الملحق V1.2 · 2026.09.12 · تقلّص النطاق | E15: =COUNTIFS('قائمة الوظائف'!$D$5:$D$517,$B15) -> 31 | F15: =COUNTIFS('قائمة الوظائف'!$D$5:$D$517,$B15,'قائمة الوظائف'!$J$5:$J$517,"المخطط التفصيلي") -> 21 | G15: =COUNTIFS('قائمة الوظائف'!$D$5:$D$517,$B15,'قائمة الوظائف'!$J$5:$J$517,"قائمة وظائف المورّد") -> 0 | H15: =COUNTIFS('قائمة الوظائف'!$D$5:$D$517,$B15,'قائمة الوظائف'!$J$5:$J$517,"من واقع الخبرة") -> 10 | I15: =COUNTIFS('قائمة الوظائف'!$D$5:$D$517,$B15,'قائمة الوظائف'!$M$5:$M$517,"نعم") -> 21 | J15: =COUNTIFS('قائمة الوظائف'!$D$5:$D$517,$B15,'قائمة الوظائف'!$L$5:$L$517,"يعمل تشغيلياً") -> 0
A16: إدارة الموارد البشرية والخدمات | B16: الرعاية الصحية | C16: Healthcare | D16: الملحق V1.2 · 2026.09.12 | E16: =COUNTIFS('قائمة الوظائف'!$D$5:$D$517,$B16) -> 31 | F16: =COUNTIFS('قائمة الوظائف'!$D$5:$D$517,$B16,'قائمة الوظائف'!$J$5:$J$517,"المخطط التفصيلي") -> 20 | G16: =COUNTIFS('قائمة الوظائف'!$D$5:$D$517,$B16,'قائمة الوظائف'!$J$5:$J$517,"قائمة وظائف المورّد") -> 0 | H16: =COUNTIFS('قائمة الوظائف'!$D$5:$D$517,$B16,'قائمة الوظائف'!$J$5:$J$517,"من واقع الخبرة") -> 11 | I16: =COUNTIFS('قائمة الوظائف'!$D$5:$D$517,$B16,'قائمة الوظائف'!$M$5:$M$517,"نعم") -> 20 | J16: =COUNTIFS('قائمة الوظائف'!$D$5:$D$517,$B16,'قائمة الوظائف'!$L$5:$L$517,"يعمل تشغيلياً") -> 0
A17: إدارة الموارد البشرية والخدمات | B17: إدارة المستندات والمراسلات | C17: Documents & Correspondence | D17: الملحق V1.0 · 2026.09.20 · تقلّص النطاق | E17: =COUNTIFS('قائمة الوظائف'!$D$5:$D$517,$B17) -> 26 | F17: =COUNTIFS('قائمة الوظائف'!$D$5:$D$517,$B17,'قائمة الوظائف'!$J$5:$J$517,"المخطط التفصيلي") -> 13 | G17: =COUNTIFS('قائمة الوظائف'!$D$5:$D$517,$B17,'قائمة الوظائف'!$J$5:$J$517,"قائمة وظائف المورّد") -> 0 | H17: =COUNTIFS('قائمة الوظائف'!$D$5:$D$517,$B17,'قائمة الوظائف'!$J$5:$J$517,"من واقع الخبرة") -> 13 | I17: =COUNTIFS('قائمة الوظائف'!$D$5:$D$517,$B17,'قائمة الوظائف'!$M$5:$M$517,"نعم") -> 13 | J17: =COUNTIFS('قائمة الوظائف'!$D$5:$D$517,$B17,'قائمة الوظائف'!$L$5:$L$517,"يعمل تشغيلياً") -> 0
A18: إدارة الموارد البشرية والخدمات | B18: إدارة المركبات | C18: Fleet Management | D18: الملحق V1.1 · 2026.09.12 · تقلّص النطاق | E18: =COUNTIFS('قائمة الوظائف'!$D$5:$D$517,$B18) -> 27 | F18: =COUNTIFS('قائمة الوظائف'!$D$5:$D$517,$B18,'قائمة الوظائف'!$J$5:$J$517,"المخطط التفصيلي") -> 15 | G18: =COUNTIFS('قائمة الوظائف'!$D$5:$D$517,$B18,'قائمة الوظائف'!$J$5:$J$517,"قائمة وظائف المورّد") -> 0 | H18: =COUNTIFS('قائمة الوظائف'!$D$5:$D$517,$B18,'قائمة الوظائف'!$J$5:$J$517,"من واقع الخبرة") -> 12 | I18: =COUNTIFS('قائمة الوظائف'!$D$5:$D$517,$B18,'قائمة الوظائف'!$M$5:$M$517,"نعم") -> 15 | J18: =COUNTIFS('قائمة الوظائف'!$D$5:$D$517,$B18,'قائمة الوظائف'!$L$5:$L$517,"يعمل تشغيلياً") -> 0
A19: إجمالي الموارد البشرية | B19: 14 تطبيق | E19: =SUM(E5:E18) -> 341 | F19: =SUM(F5:F18) -> 172 | G19: =SUM(G5:G18) -> 83 | H19: =SUM(H5:H18) -> 86 | I19: =SUM(I5:I18) -> 255 | J19: =SUM(J5:J18) -> 69
A20: الإدارة المالية | B20: المحاسبة | C20: Accounting | E20: =COUNTIFS('قائمة الوظائف'!$D$5:$D$517,$B20) -> 15 | F20: =COUNTIFS('قائمة الوظائف'!$D$5:$D$517,$B20,'قائمة الوظائف'!$J$5:$J$517,"المخطط التفصيلي") -> 7 | G20: =COUNTIFS('قائمة الوظائف'!$D$5:$D$517,$B20,'قائمة الوظائف'!$J$5:$J$517,"قائمة وظائف المورّد") -> 4 | H20: =COUNTIFS('قائمة الوظائف'!$D$5:$D$517,$B20,'قائمة الوظائف'!$J$5:$J$517,"من واقع الخبرة") -> 4 | I20: =COUNTIFS('قائمة الوظائف'!$D$5:$D$517,$B20,'قائمة الوظائف'!$M$5:$M$517,"نعم") -> 11 | J20: =COUNTIFS('قائمة الوظائف'!$D$5:$D$517,$B20,'قائمة الوظائف'!$L$5:$L$517,"يعمل تشغيلياً") -> 4
A21: الإدارة المالية | B21: المدفوعات | C21: Payments | E21: =COUNTIFS('قائمة الوظائف'!$D$5:$D$517,$B21) -> 19 | F21: =COUNTIFS('قائمة الوظائف'!$D$5:$D$517,$B21,'قائمة الوظائف'!$J$5:$J$517,"المخطط التفصيلي") -> 10 | G21: =COUNTIFS('قائمة الوظائف'!$D$5:$D$517,$B21,'قائمة الوظائف'!$J$5:$J$517,"قائمة وظائف المورّد") -> 5 | H21: =COUNTIFS('قائمة الوظائف'!$D$5:$D$517,$B21,'قائمة الوظائف'!$J$5:$J$517,"من واقع الخبرة") -> 4 | I21: =COUNTIFS('قائمة الوظائف'!$D$5:$D$517,$B21,'قائمة الوظائف'!$M$5:$M$517,"نعم") -> 15 | J21: =COUNTIFS('قائمة الوظائف'!$D$5:$D$517,$B21,'قائمة الوظائف'!$L$5:$L$517,"يعمل تشغيلياً") -> 2
A22: الإدارة المالية | B22: المقبوضات | C22: Receipts | E22: =COUNTIFS('قائمة الوظائف'!$D$5:$D$517,$B22) -> 14 | F22: =COUNTIFS('قائمة الوظائف'!$D$5:$D$517,$B22,'قائمة الوظائف'!$J$5:$J$517,"المخطط التفصيلي") -> 7 | G22: =COUNTIFS('قائمة الوظائف'!$D$5:$D$517,$B22,'قائمة الوظائف'!$J$5:$J$517,"قائمة وظائف المورّد") -> 4 | H22: =COUNTIFS('قائمة الوظائف'!$D$5:$D$517,$B22,'قائمة الوظائف'!$J$5:$J$517,"من واقع الخبرة") -> 3 | I22: =COUNTIFS('قائمة الوظائف'!$D$5:$D$517,$B22,'قائمة الوظائف'!$M$5:$M$517,"نعم") -> 11 | J22: =COUNTIFS('قائمة الوظائف'!$D$5:$D$517,$B22,'قائمة الوظائف'!$L$5:$L$517,"يعمل تشغيلياً") -> 2
A23: الإدارة المالية | B23: الأصول الثابتة | C23: Fixed Assets | E23: =COUNTIFS('قائمة الوظائف'!$D$5:$D$517,$B23) -> 11 | F23: =COUNTIFS('قائمة الوظائف'!$D$5:$D$517,$B23,'قائمة الوظائف'!$J$5:$J$517,"المخطط التفصيلي") -> 4 | G23: =COUNTIFS('قائمة الوظائف'!$D$5:$D$517,$B23,'قائمة الوظائف'!$J$5:$J$517,"قائمة وظائف المورّد") -> 1 | H23: =COUNTIFS('قائمة الوظائف'!$D$5:$D$517,$B23,'قائمة الوظائف'!$J$5:$J$517,"من واقع الخبرة") -> 6 | I23: =COUNTIFS('قائمة الوظائف'!$D$5:$D$517,$B23,'قائمة الوظائف'!$M$5:$M$517,"نعم") -> 5 | J23: =COUNTIFS('قائمة الوظائف'!$D$5:$D$517,$B23,'قائمة الوظائف'!$L$5:$L$517,"يعمل تشغيلياً") -> 1
A24: الإدارة المالية | B24: الاعتمادات المستندية | C24: Letters of Credit | D24: وحدة غير واردة في المخطط | E24: =COUNTIFS('قائمة الوظائف'!$D$5:$D$517,$B24) -> 7 | F24: =COUNTIFS('قائمة الوظائف'!$D$5:$D$517,$B24,'قائمة الوظائف'!$J$5:$J$517,"المخطط التفصيلي") -> 0 | G24: =COUNTIFS('قائمة الوظائف'!$D$5:$D$517,$B24,'قائمة الوظائف'!$J$5:$J$517,"قائمة وظائف المورّد") -> 7 | H24: =COUNTIFS('قائمة الوظائف'!$D$5:$D$517,$B24,'قائمة الوظائف'!$J$5:$J$517,"من واقع الخبرة") -> 0 | I24: =COUNTIFS('قائمة الوظائف'!$D$5:$D$517,$B24,'قائمة الوظائف'!$M$5:$M$517,"نعم") -> 7 | J24: =COUNTIFS('قائمة الوظائف'!$D$5:$D$517,$B24,'قائمة الوظائف'!$L$5:$L$517,"يعمل تشغيلياً") -> 4
A25: الإدارة المالية | B25: دورة حياة العقود | C25: Contract Lifecycle | E25: =COUNTIFS('قائمة الوظائف'!$D$5:$D$517,$B25) -> 18 | F25: =COUNTIFS('قائمة الوظائف'!$D$5:$D$517,$B25,'قائمة الوظائف'!$J$5:$J$517,"المخطط التفصيلي") -> 9 | G25: =COUNTIFS('قائمة الوظائف'!$D$5:$D$517,$B25,'قائمة الوظائف'!$J$5:$J$517,"قائمة وظائف المورّد") -> 1 | H25: =COUNTIFS('قائمة الوظائف'!$D$5:$D$517,$B25,'قائمة الوظائف'!$J$5:$J$517,"من واقع الخبرة") -> 8 | I25: =COUNTIFS('قائمة الوظائف'!$D$5:$D$517,$B25,'قائمة الوظائف'!$M$5:$M$517,"نعم") -> 10 | J25: =COUNTIFS('قائمة الوظائف'!$D$5:$D$517,$B25,'قائمة الوظائف'!$L$5:$L$517,"يعمل تشغيلياً") -> 0
A26: إجمالي المالية | B26: 6 تطبيق | E26: =SUM(E20:E25) -> 84 | F26: =SUM(F20:F25) -> 37 | G26: =SUM(G20:G25) -> 22 | H26: =SUM(H20:H25) -> 25 | I26: =SUM(I20:I25) -> 59 | J26: =SUM(J20:J25) -> 13
A27: الإدارة التجارية | B27: المبيعات | C27: Sales | E27: =COUNTIFS('قائمة الوظائف'!$D$5:$D$517,$B27) -> 21 | F27: =COUNTIFS('قائمة الوظائف'!$D$5:$D$517,$B27,'قائمة الوظائف'!$J$5:$J$517,"المخطط التفصيلي") -> 10 | G27: =COUNTIFS('قائمة الوظائف'!$D$5:$D$517,$B27,'قائمة الوظائف'!$J$5:$J$517,"قائمة وظائف المورّد") -> 7 | H27: =COUNTIFS('قائمة الوظائف'!$D$5:$D$517,$B27,'قائمة الوظائف'!$J$5:$J$517,"من واقع الخبرة") -> 4 | I27: =COUNTIFS('قائمة الوظائف'!$D$5:$D$517,$B27,'قائمة الوظائف'!$M$5:$M$517,"نعم") -> 17 | J27: =COUNTIFS('قائمة الوظائف'!$D$5:$D$517,$B27,'قائمة الوظائف'!$L$5:$L$517,"يعمل تشغيلياً") -> 2
A28: الإدارة التجارية | B28: خدمات المشتركين | C28: Subscriber Services | E28: =COUNTIFS('قائمة الوظائف'!$D$5:$D$517,$B28) -> 3 | F28: =COUNTIFS('قائمة الوظائف'!$D$5:$D$517,$B28,'قائمة الوظائف'!$J$5:$J$517,"المخطط التفصيلي") -> 0 | G28: =COUNTIFS('قائمة الوظائف'!$D$5:$D$517,$B28,'قائمة الوظائف'!$J$5:$J$517,"قائمة وظائف المورّد") -> 1 | H28: =COUNTIFS('قائمة الوظائف'!$D$5:$D$517,$B28,'قائمة الوظائف'!$J$5:$J$517,"من واقع الخبرة") -> 2 | I28: =COUNTIFS('قائمة الوظائف'!$D$5:$D$517,$B28,'قائمة الوظائف'!$M$5:$M$517,"نعم") -> 1 | J28: =COUNTIFS('قائمة الوظائف'!$D$5:$D$517,$B28,'قائمة الوظائف'!$L$5:$L$517,"يعمل تشغيلياً") -> 0
A29: إجمالي التجارية | B29: 2 تطبيق | E29: =SUM(E27:E28) -> 24 | F29: =SUM(F27:F28) -> 10 | G29: =SUM(G27:G28) -> 8 | H29: =SUM(H27:H28) -> 6 | I29: =SUM(I27:I28) -> 18 | J29: =SUM(J27:J28) -> 2
A30: التهيئة والبنية التحتية والمتطلبات | B30: الخوادم والتخزين | C30: Servers & Storage | E30: =COUNTIFS('قائمة الوظائف'!$D$5:$D$517,$B30) -> 8 | F30: =COUNTIFS('قائمة الوظائف'!$D$5:$D$517,$B30,'قائمة الوظائف'!$J$5:$J$517,"المخطط التفصيلي") -> 3 | G30: =COUNTIFS('قائمة الوظائف'!$D$5:$D$517,$B30,'قائمة الوظائف'!$J$5:$J$517,"قائمة وظائف المورّد") -> 1 | H30: =COUNTIFS('قائمة الوظائف'!$D$5:$D$517,$B30,'قائمة الوظائف'!$J$5:$J$517,"من واقع الخبرة") -> 4 | I30: =COUNTIFS('قائمة الوظائف'!$D$5:$D$517,$B30,'قائمة الوظائف'!$M$5:$M$517,"نعم") -> 4 | J30: =COUNTIFS('قائمة الوظائف'!$D$5:$D$517,$B30,'قائمة الوظائف'!$L$5:$L$517,"يعمل تشغيلياً") -> 1
A31: التهيئة والبنية التحتية والمتطلبات | B31: قاعدة البيانات والتراخيص | C31: Database & Licences | E31: =COUNTIFS('قائمة الوظائف'!$D$5:$D$517,$B31) -> 8 | F31: =COUNTIFS('قائمة الوظائف'!$D$5:$D$517,$B31,'قائمة الوظائف'!$J$5:$J$517,"المخطط التفصيلي") -> 2 | G31: =COUNTIFS('قائمة الوظائف'!$D$5:$D$517,$B31,'قائمة الوظائف'!$J$5:$J$517,"قائمة وظائف المورّد") -> 1 | H31: =COUNTIFS('قائمة الوظائف'!$D$5:$D$517,$B31,'قائمة الوظائف'!$J$5:$J$517,"من واقع الخبرة") -> 5 | I31: =COUNTIFS('قائمة الوظائف'!$D$5:$D$517,$B31,'قائمة الوظائف'!$M$5:$M$517,"نعم") -> 3 | J31: =COUNTIFS('قائمة الوظائف'!$D$5:$D$517,$B31,'قائمة الوظائف'!$L$5:$L$517,"يعمل تشغيلياً") -> 1
A32: التهيئة والبنية التحتية والمتطلبات | B32: الشبكة والربط بالفروع | C32: Network & Branch Connectivity | E32: =COUNTIFS('قائمة الوظائف'!$D$5:$D$517,$B32) -> 9 | F32: =COUNTIFS('قائمة الوظائف'!$D$5:$D$517,$B32,'قائمة الوظائف'!$J$5:$J$517,"المخطط التفصيلي") -> 2 | G32: =COUNTIFS('قائمة الوظائف'!$D$5:$D$517,$B32,'قائمة الوظائف'!$J$5:$J$517,"قائمة وظائف المورّد") -> 2 | H32: =COUNTIFS('قائمة الوظائف'!$D$5:$D$517,$B32,'قائمة الوظائف'!$J$5:$J$517,"من واقع الخبرة") -> 5 | I32: =COUNTIFS('قائمة الوظائف'!$D$5:$D$517,$B32,'قائمة الوظائف'!$M$5:$M$517,"نعم") -> 4 | J32: =COUNTIFS('قائمة الوظائف'!$D$5:$D$517,$B32,'قائمة الوظائف'!$L$5:$L$517,"يعمل تشغيلياً") -> 2
A33: التهيئة والبنية التحتية والمتطلبات | B33: بيئات العمل والنشر | C33: Environments & Deployment | E33: =COUNTIFS('قائمة الوظائف'!$D$5:$D$517,$B33) -> 6 | F33: =COUNTIFS('قائمة الوظائف'!$D$5:$D$517,$B33,'قائمة الوظائف'!$J$5:$J$517,"المخطط التفصيلي") -> 0 | G33: =COUNTIFS('قائمة الوظائف'!$D$5:$D$517,$B33,'قائمة الوظائف'!$J$5:$J$517,"قائمة وظائف المورّد") -> 2 | H33: =COUNTIFS('قائمة الوظائف'!$D$5:$D$517,$B33,'قائمة الوظائف'!$J$5:$J$517,"من واقع الخبرة") -> 4 | I33: =COUNTIFS('قائمة الوظائف'!$D$5:$D$517,$B33,'قائمة الوظائف'!$M$5:$M$517,"نعم") -> 2 | J33: =COUNTIFS('قائمة الوظائف'!$D$5:$D$517,$B33,'قائمة الوظائف'!$L$5:$L$517,"يعمل تشغيلياً") -> 2
A34: التهيئة والبنية التحتية والمتطلبات | B34: النسخ الاحتياطي والتعافي | C34: Backup & Recovery | E34: =COUNTIFS('قائمة الوظائف'!$D$5:$D$517,$B34) -> 5 | F34: =COUNTIFS('قائمة الوظائف'!$D$5:$D$517,$B34,'قائمة الوظائف'!$J$5:$J$517,"المخطط التفصيلي") -> 0 | G34: =COUNTIFS('قائمة الوظائف'!$D$5:$D$517,$B34,'قائمة الوظائف'!$J$5:$J$517,"قائمة وظائف المورّد") -> 1 | H34: =COUNTIFS('قائمة الوظائف'!$D$5:$D$517,$B34,'قائمة الوظائف'!$J$5:$J$517,"من واقع الخبرة") -> 4 | I34: =COUNTIFS('قائمة الوظائف'!$D$5:$D$517,$B34,'قائمة الوظائف'!$M$5:$M$517,"نعم") -> 1 | J34: =COUNTIFS('قائمة الوظائف'!$D$5:$D$517,$B34,'قائمة الوظائف'!$L$5:$L$517,"يعمل تشغيلياً") -> 1
A35: التهيئة والبنية التحتية والمتطلبات | B35: الأمن والصلاحيات والتسليم | C35: Security, Permissions & Handover | E35: =COUNTIFS('قائمة الوظائف'!$D$5:$D$517,$B35) -> 10 | F35: =COUNTIFS('قائمة الوظائف'!$D$5:$D$517,$B35,'قائمة الوظائف'!$J$5:$J$517,"المخطط التفصيلي") -> 2 | G35: =COUNTIFS('قائمة الوظائف'!$D$5:$D$517,$B35,'قائمة الوظائف'!$J$5:$J$517,"قائمة وظائف المورّد") -> 4 | H35: =COUNTIFS('قائمة الوظائف'!$D$5:$D$517,$B35,'قائمة الوظائف'!$J$5:$J$517,"من واقع الخبرة") -> 4 | I35: =COUNTIFS('قائمة الوظائف'!$D$5:$D$517,$B35,'قائمة الوظائف'!$M$5:$M$517,"نعم") -> 6 | J35: =COUNTIFS('قائمة الوظائف'!$D$5:$D$517,$B35,'قائمة الوظائف'!$L$5:$L$517,"يعمل تشغيلياً") -> 2
A36: التهيئة والبنية التحتية والمتطلبات | B36: ترحيل البيانات | C36: Data Migration | E36: =COUNTIFS('قائمة الوظائف'!$D$5:$D$517,$B36) -> 10 | F36: =COUNTIFS('قائمة الوظائف'!$D$5:$D$517,$B36,'قائمة الوظائف'!$J$5:$J$517,"المخطط التفصيلي") -> 2 | G36: =COUNTIFS('قائمة الوظائف'!$D$5:$D$517,$B36,'قائمة الوظائف'!$J$5:$J$517,"قائمة وظائف المورّد") -> 1 | H36: =COUNTIFS('قائمة الوظائف'!$D$5:$D$517,$B36,'قائمة الوظائف'!$J$5:$J$517,"من واقع الخبرة") -> 7 | I36: =COUNTIFS('قائمة الوظائف'!$D$5:$D$517,$B36,'قائمة الوظائف'!$M$5:$M$517,"نعم") -> 3 | J36: =COUNTIFS('قائمة الوظائف'!$D$5:$D$517,$B36,'قائمة الوظائف'!$L$5:$L$517,"يعمل تشغيلياً") -> 1
A37: التهيئة والبنية التحتية والمتطلبات | B37: التدريب ونقل المعرفة | C37: Training & Knowledge Transfer | E37: =COUNTIFS('قائمة الوظائف'!$D$5:$D$517,$B37) -> 8 | F37: =COUNTIFS('قائمة الوظائف'!$D$5:$D$517,$B37,'قائمة الوظائف'!$J$5:$J$517,"المخطط التفصيلي") -> 2 | G37: =COUNTIFS('قائمة الوظائف'!$D$5:$D$517,$B37,'قائمة الوظائف'!$J$5:$J$517,"قائمة وظائف المورّد") -> 0 | H37: =COUNTIFS('قائمة الوظائف'!$D$5:$D$517,$B37,'قائمة الوظائف'!$J$5:$J$517,"من واقع الخبرة") -> 6 | I37: =COUNTIFS('قائمة الوظائف'!$D$5:$D$517,$B37,'قائمة الوظائف'!$M$5:$M$517,"نعم") -> 2 | J37: =COUNTIFS('قائمة الوظائف'!$D$5:$D$517,$B37,'قائمة الوظائف'!$L$5:$L$517,"يعمل تشغيلياً") -> 0
A38: إجمالي البنية التحتية | B38: 8 تطبيق | E38: =SUM(E30:E37) -> 64 | F38: =SUM(F30:F37) -> 13 | G38: =SUM(G30:G37) -> 12 | H38: =SUM(H30:H37) -> 39 | I38: =SUM(I30:I37) -> 25 | J38: =SUM(J30:J37) -> 10
A39: الإجمالي العام | B39: 30 تطبيق | E39: =E19+E26+E29+E38 -> 513 | F39: =F19+F26+F29+F38 -> 232 | G39: =G19+G26+G29+G38 -> 125 | H39: =H19+H26+H29+H38 -> 156 | I39: =I19+I26+I29+I38 -> 357 | J39: =J19+J26+J29+J38 -> 94
A41: تحقق: عدد صفوف القائمة | E41: =COUNTA('قائمة الوظائف'!$H$5:$H$517) -> 513 | F41: =IF(E41=E39,"مطابق","غير مطابق") -> مطابق

Sheet قائمة الوظائف
A1: قائمة الوظائف الكاملة حسب الموديول (الإدارة) والتطبيق — نظام متابعة إنجاز ERP
A2: المصدر: كتالوج النظام (backend/src/db/seed/catalog.json) المستخرج من ملف المتابعة الأصلي erp-tracker-original.html — مطابق له 100%. لا تشمل الوظائف المضافة أو المُزالة لاحقاً على الخادم.
A4: م | B4: الموديول (الإدارة) | C4: Module | D4: التطبيق | E4: Application | F4: رمز التطبيق | G4: تابع لـ / ملاحظات التطبيق | H4: رمز الوظيفة | I4: اسم الوظيفة | J4: المصدر | K4: المرجع | L4: حالة المورّد المعلنة | M4: محسوبة في النسب افتراضياً
A5: 1 | B5: إدارة الموارد البشرية والخدمات | C5: Human Resources & Services | D5: شؤون العاملين | E5: Personnel Affairs | F5: per | H5: D0 | I5: الوظائف والدرجة الوظيفية وفترة الاختبار | J5: المخطط التفصيلي | K5: ص 69 | L5: — | M5: نعم
A6: 2 | B6: إدارة الموارد البشرية والخدمات | C6: Human Resources & Services | D6: شؤون العاملين | E6: Personnel Affairs | F6: per | H6: D1 | I6: المواقع الوظيفية ومقارنة الخطة بالتوظيف الفعلي | J6: المخطط التفصيلي | K6: ص 69 | L6: — | M6: نعم
A7: 3 | B7: إدارة الموارد البشرية والخدمات | C7: Human Resources & Services | D7: شؤون العاملين | E7: Personnel Affairs | F7: per | H7: D2 | I7: الهيكل الإداري والوظيفي الديناميكي وربط الموظف بالوظيفة الإشرافية | J7: المخطط التفصيلي | K7: ص 92 | L7: — | M7: نعم
A8: 4 | B8: إدارة الموارد البشرية والخدمات | C8: Human Resources & Services | D8: شؤون العاملين | E8: Personnel Affairs | F8: per | H8: D3 | I8: البيانات الشخصية: الاسم، المؤهل، الجنس، الرقم الوطني، الميلاد، الحالة الاجتماعية، الهواتف، الرقم الضماني، جواز السفر، العنوان بإحداثيات | J8: المخطط التفصيلي | K8: ص 92 | L8: — | M8: نعم
A9: 5 | B9: إدارة الموارد البشرية والخدمات | C9: Human Resources & Services | D9: شؤون العاملين | E9: Personnel Affairs | F9: per | H9: D4 | I9: عقد العمل: تاريخ التعيين والوظيفة والمرتب، الإصدار الآلي للعقود، النقل بين الإدارات | J9: المخطط التفصيلي | K9: ص 92 | L9: — | M9: نعم
A10: 6 | B10: إدارة الموارد البشرية والخدمات | C10: Human Resources & Services | D10: شؤون العاملين | E10: Personnel Affairs | F10: per | H10: D5 | I10: مسوغات التعيين حسب الوظيفة والجنس والجنسية | J10: المخطط التفصيلي | K10: ص 92 | L10: — | M10: نعم
A11: 7 | B11: إدارة الموارد البشرية والخدمات | C11: Human Resources & Services | D11: شؤون العاملين | E11: Personnel Affairs | F11: per | H11: D6 | I11: أمر تكليف العمل | J11: المخطط التفصيلي | K11: ص 92 | L11: — | M11: نعم
A12: 8 | B12: إدارة الموارد البشرية والخدمات | C12: Human Resources & Services | D12: شؤون العاملين | E12: Personnel Affairs | F12: per | H12: D7 | I12: أرشفة بيانات الموظف وتعريف بصمته | J12: المخطط التفصيلي | K12: ص 64 | L12: — | M12: نعم
A13: 9 | B13: إدارة الموارد البشرية والخدمات | C13: Human Resources & Services | D13: شؤون العاملين | E13: Personnel Affairs | F13: per | H13: D8 | I13: دليل جهات التعامل للمأموريات والاجتماعات بموقع GPS | J13: المخطط التفصيلي | K13: ص 92 | L13: — | M13: نعم
A14: 10 | B14: إدارة الموارد البشرية والخدمات | C14: Human Resources & Services | D14: شؤون العاملين | E14: Personnel Affairs | F14: per | H14: D9 | I14: قوالب خطابات شؤون العاملين وتصنيفها في مجلدات | J14: المخطط التفصيلي | K14: ص 93 | L14: — | M14: نعم
A15: 11 | B15: إدارة الموارد البشرية والخدمات | C15: Human Resources & Services | D15: شؤون العاملين | E15: Personnel Affairs | F15: per | H15: D10 | I15: طلب خطاب شؤون عاملين عبر الخدمة الذاتية | J15: المخطط التفصيلي | K15: ص 93 | L15: — | M15: نعم
A16: 12 | B16: إدارة الموارد البشرية والخدمات | C16: Human Resources & Services | D16: شؤون العاملين | E16: Personnel Affairs | F16: per | H16: D11 | I16: العهد العينية والمالية: التصنيف، الرقم المسلسل، الحالة، تاريخ الشراء، المكان، آلية الصرف وإقرار الاستلام، الاستيراد من إكسيل | J16: المخطط التفصيلي | K16: ص 93 و95 | L16: — | M16: نعم
... A44: 40 | B44: إدارة الموارد البشرية والخدمات | C44: Human Resources & Services | D44: شؤون العاملين | E44: Personnel Affairs | F44: per | H44: X6 | I44: رقم اشتراك الضمان الاجتماعي وحالته | J44: من واقع الخبرة | K44: الوثيقة تحفظ «الرقم الضماني» كحقل فقط دون دورة اشتراك | L44: — | M44: لا (مقترح)
A45: 41 | B45: إدارة الموارد البشرية والخدمات | C45: Human Resources & Services | D45: التوظيف | E45: Recruitment | F45: rec | G45: ضمن شؤون العاملين | H45: D0 | I45: إعدادات التوظيف: حقول استمارة التوظيف وأسئلة التقييم | J45: المخطط التفصيلي | K45: ص 69 | L45: — | M45: نعم
A46: 42 | B46: إدارة الموارد البشرية والخدمات | C46: Human Resources & Services | D46: التوظيف | E46: Recruitment | F46: rec | G46: ضمن شؤون العاملين | H46: D1 | I46: مسارات اعتماد طلبات التوظيف | J46: المخطط التفصيلي | K46: ص 69 | L46: — | M46: نعم
A47: 43 | B47: إدارة الموارد البشرية والخدمات | C47: Human Resources & Services | D47: التوظيف | E47: Recruitment | F47: rec | G47: ضمن شؤون العاملين | H47: D2 | I47: طلب التوظيف من الإدارة الطالبة: المدير، التاريخ، العدد، المهارات | J47: المخطط التفصيلي | K47: ص 69 | L47: — | M47: نعم
A48: 44 | B48: إدارة الموارد البشرية والخدمات | C48: Human Resources & Services | D48: التوظيف | E48: Recruitment | F48: rec | G48: ضمن شؤون العاملين | H48: D3 | I48: تجميع طلبات التوظيف وإنشاء إعلانات منها | J48: المخطط التفصيلي | K48: ص 69 | L48: — | M48: نعم
A49: 45 | B49: إدارة الموارد البشرية والخدمات | C49: Human Resources & Services | D49: التوظيف | E49: Recruitment | F49: rec | G49: ضمن شؤون العاملين | H49: D4 | I49: نشر الإعلانات على منصات التوظيف ومتابعة المنشور والسابق | J49: المخطط التفصيلي | K49: ص 69 و64 | L49: — | M49: نعم
A50: 46 | B50: إدارة الموارد البشرية والخدمات | C50: Human Resources & Services | D50: التوظيف | E50: Recruitment | F50: rec | G50: ضمن شؤون العاملين | H50: D5 | I50: استمارات المتقدمين لكل وظيفة | J50: المخطط التفصيلي | K50: ص 69 | L50: — | M50: نعم
A51: 47 | B51: إدارة الموارد البشرية والخدمات | C51: Human Resources & Services | D51: التوظيف | E51: Recruitment | F51: rec | G51: ضمن شؤون العاملين | H51: D6 | I51: تصنيف المتقدمين مطابق/غير مطابق بالذكاء الاصطناعي | J51: المخطط التفصيلي | K51: ص 69 و64 | L51: — | M51: نعم
A52: 48 | B52: إدارة الموارد البشرية والخدمات | C52: Human Resources & Services | D52: التوظيف | E52: Recruitment | F52: rec | G52: ضمن شؤون العاملين | H52: D7 | I52: تقييم المتقدمين من لجنة التوظيف | J52: المخطط التفصيلي | K52: ص 69 | L52: — | M52: نعم
A53: 49 | B53: إدارة الموارد البشرية والخدمات | C53: Human Resources & Services | D53: التوظيف | E53: Recruitment | F53: rec | G53: ضمن شؤون العاملين | H53: D8 | I53: إجراءات التوظيف والتأكد من بيانات المرشحين المقبولين | J53: المخطط التفصيلي | K53: ص 69 | L53: — | M53: نعم
A54: 50 | B54: إدارة الموارد البشرية والخدمات | C54: Human Resources & Services | D54: التوظيف | E54: Recruitment | F54: rec | G54: ضمن شؤون العاملين | H54: D9 | I54: إعداد العرض الوظيفي | J54: المخطط التفصيلي | K54: ص 64 | L54: — | M54: نعم
A55: 51 | B55: إدارة الموارد البشرية والخدمات | C55: Human Resources & Services | D55: التوظيف | E55: Recruitment | F55: rec | G55: ضمن شؤون العاملين | H55: D10 | I55: طلب مسوغات التعيين | J55: المخطط التفصيلي | K55: ص 64 | L55: — | M55: نعم
A56: 52 | B56: إدارة الموارد البشرية والخدمات | C56: Human Resources & Services | D56: التوظيف | E56: Recruitment | F56: rec | G56: ضمن شؤون العاملين | H56: D11 | I56: إعداد الرسالة المباشرة | J56: المخطط التفصيلي | K56: ص 64 | L56: — | M56: نعم
... A59: 55 | B59: إدارة الموارد البشرية والخدمات | C59: Human Resources & Services | D59: التوظيف | E59: Recruitment | F59: rec | G59: ضمن شؤون العاملين | H59: X0 | I59: الملاك المعتمد مقابل الفعلي وربطه بموازنة التوظيف | J59: من واقع الخبرة | K59: المواقع الوظيفية موجودة دون ربطها بسقف مالي، فيمرّ التوظيف دون رقابة ميزانية | L59: — | M59: لا (مقترح)
A60: 56 | B60: إدارة الموارد البشرية والخدمات | C60: Human Resources & Services | D60: الحضور والانصراف | E60: Time & Attendance | F60: att | H60: D0 | I60: ربط أجهزة البصمة ZK وBio star وNitgen وsystem max، وربط أجهزة كل فرع على حدة، والمزامنة التلقائية | J60: المخطط التفصيلي | K60: ص 95 | L60: — | M60: نعم
A61: 57 | B61: إدارة الموارد البشرية والخدمات | C61: Human Resources & Services | D61: الحضور والانصراف | E61: Time & Attendance | F61: att | H61: D1 | I61: جداول الأعمال: يومي، أسبوعي، شهري، سنوي | J61: المخطط التفصيلي | K61: ص 95 | L61: — | M61: نعم
A62: 58 | B62: إدارة الموارد البشرية والخدمات | C62: Human Resources & Services | D62: الحضور والانصراف | E62: Time & Attendance | F62: att | H62: D2 | I62: الورديات النظامية والتناوبية، وإضافة وتعديل وردية بديلة | J62: المخطط التفصيلي | K62: ص 95 | L62: — | M62: نعم
A63: 59 | B63: إدارة الموارد البشرية والخدمات | C63: Human Resources & Services | D63: الحضور والانصراف | E63: Time & Attendance | F63: att | H63: D3 | I63: تعددية فترات السماح ومرونة أوقات الحضور والانصراف | J63: المخطط التفصيلي | K63: ص 95 | L63: — | M63: نعم
A64: 60 | B64: إدارة الموارد البشرية والخدمات | C64: Human Resources & Services | D64: الحضور والانصراف | E64: Time & Attendance | F64: att | H64: D4 | I64: حضور الموقع عبر GPS من تطبيق الهاتف | J64: المخطط التفصيلي | K64: ص 83 | L64: — | M64: نعم
A65: 61 | B65: إدارة الموارد البشرية والخدمات | C65: Human Resources & Services | D65: الحضور والانصراف | E65: Time & Attendance | F65: att | H65: D5 | I65: طلب الالتماس عند نسيان التوقيع | J65: المخطط التفصيلي | K65: عرض فني ص 68 | L65: — | M65: نعم
A66: 62 | B66: إدارة الموارد البشرية والخدمات | C66: Human Resources & Services | D66: الحضور والانصراف | E66: Time & Attendance | F66: att | H66: D6 | I66: سياسة الأذون الخاصة بسقف شهري دون خصم | J66: المخطط التفصيلي | K66: ص 94 | L66: — | M66: نعم
A67: 63 | B67: إدارة الموارد البشرية والخدمات | C67: Human Resources & Services | D67: الحضور والانصراف | E67: Time & Attendance | F67: att | H67: D7 | I67: الوقت الإضافي واحتساب نقاطه | J67: المخطط التفصيلي | K67: ص 96 | L67: — | M67: نعم
A68: 64 | B68: إدارة الموارد البشرية والخدمات | C68: Human Resources & Services | D68: الحضور والانصراف | E68: Time & Attendance | F68: att | H68: D8 | I68: نظام الانقطاع عن العمل: لوائحه ودوريته ومراقبة المتصل والمنفصل | J68: المخطط التفصيلي | K68: ص 95 | L68: — | M68: نعم
A69: 65 | B69: إدارة الموارد البشرية والخدمات | C69: Human Resources & Services | D69: الحضور والانصراف | E69: Time & Attendance | F69: att | H69: D9 | I69: لوائح جزاءات التأخير والغياب وتصاعدها عند التكرار | J69: المخطط التفصيلي | K69: ص 94 | L69: — | M69: نعم
A70: 66 | B70: إدارة الموارد البشرية والخدمات | C70: Human Resources & Services | D70: الحضور والانصراف | E70: Time & Attendance | F70: att | H70: D10 | I70: العطلات الرسمية وحالتها مدفوعة من عدمها وتخصيصها لفروع | J70: المخطط التفصيلي | K70: ص 92 | L70: — | M70: نعم
...
